# Comparison: Custom tryCatch Utility vs Neverthrow

## Overview

This document compares our custom `tryCatch` utility with the [neverthrow](https://github.com/supermacro/neverthrow) npm package for handling errors in a functional way.

## Comparison Summary

| Feature                | Custom tryCatch              | Neverthrow                 |
| ---------------------- | ---------------------------- | -------------------------- |
| **Approach**           | Simple Promise wrapper       | Comprehensive Result monad |
| **Learning Curve**     | Low - familiar syntax        | Medium - new concepts      |
| **Type Safety**        | Good                         | Excellent                  |
| **Composability**      | Limited                      | Extensive                  |
| **Bundle Size**        | Zero additional              | Small (~4KB)               |
| **Flexibility**        | Basic success/error handling | Rich API with combinators  |
| **Integration Effort** | Minimal changes              | Moderate refactoring       |
| **Error Type Safety**  | Basic with enhancement       | Comprehensive              |

## Custom tryCatch Utility

Our custom utility provides a simple wrapper around try/catch blocks:

```typescript
// Result type with discriminated union
interface Success<T> {
	data: T
	error: null
}

interface Failure<E> {
	data: null
	error: E
}

type Result<T, E = Error> = Success<T> | Failure<E>

// Main wrapper function
const tryCatch = async <T, E = Error>(
	promise: Promise<T>,
): Promise<Result<T, E>> => {
	try {
		const data = await promise
		return { data, error: null }
	} catch (error: unknown) {
		return { data: null, error: error as E }
	}
}
```

### Advantages:

- Familiar pattern for JavaScript developers
- Easy to adopt incrementally
- No external dependencies
- Simple mental model

### Disadvantages:

- Limited composability
- No built-in combinators for complex flows
- Manual error handling in each consumer
- Less powerful type inference

## Neverthrow

Neverthrow is a robust library that implements the Result monad pattern:

```typescript
import { Result, ok, err } from 'neverthrow'

// Function that returns a Result
function divide(a: number, b: number): Result<number, string> {
	if (b === 0) {
		return err('Cannot divide by zero')
	}
	return ok(a / b)
}
```

### Advantages:

- Strong type safety
- Rich API for composition (map, mapErr, andThen, etc.)
- Encourages explicit error handling
- Prevents runtime exceptions
- Chainable operations

### Disadvantages:

- Steeper learning curve
- Requires more upfront refactoring
- External dependency
- Different programming paradigm

## Code Examples: Registration Flow

### Current Implementation with tryCatch

#### 1. Route Handler

```typescript
// auth.routes.ts
router.post(
	'/register',
	validateRequest(registerUserRequestSchema),
	authController.register,
)
```

#### 2. Controller

```typescript
// auth.controller.ts
register: async (req: Request, res: Response) => {
	const { email, password, confirmPassword } = req.body as TRegisterUserRequest

	const { data: response, error } = await tryCatch(
		cognito.signUpUser({ email, password, confirmPassword }),
	)

	if (error) {
		logger.error(`[authController]: Error registering user: ${error}`)
		const err = standardizeError(error)
		handleError(res, err, 'authController')
		return
	}

	if (!response.UserSub) {
		const error = AppError.validation('User not created - no user ID returned')
		handleError(res, standardizeError(error), 'authController')
		return
	}

	const { data: user, error: userError } = await tryCatch(
		createUser({ id: response.UserSub, email }),
	)

	if (userError) {
		logger.error(
			`[authController]: Error creating user in database: ${userError}`,
		)
		const err = standardizeError(userError)
		handleError(res, err, 'authController')
		return
	}

	logger.info(`[authController]: User created: ${user.id}`)

	const authResponse: TRegisterUserResponse = {
		message:
			'Registration successful. Please check your email for verification code.',
		user: {
			id: response.UserSub,
			email,
		},
	}

	res.status(StatusCodes.CREATED).json(authResponse)
}
```

#### 3. Service

```typescript
// auth.services.ts
public async signUpUser({
  email,
  password,
  confirmPassword,
}: TRegisterUserRequest) {
  if (password !== confirmPassword) {
    throw AppError.validation('Passwords do not match', undefined, 'authService')
  }

  const userId = crypto.randomUUID()

  const command = new SignUpCommand({
    ClientId: this.clientId,
    Username: userId,
    Password: password,
    UserAttributes: [
      {
        Name: 'email',
        Value: email,
      },
    ],
    SecretHash: this.generateHash(userId),
  })

  return this.client.send(command)
}
```

#### 4. Data Access

```typescript
// user.data-access.ts
const createUser = async (userData: TInsertUser): Promise<TUser> => {
	try {
		const validatedData = insertUserSchema.parse(userData)

		const [user] = await db.insert(usersTable).values(validatedData).returning()

		return selectUserSchema.parse(user)
	} catch (error) {
		logger.error(`[userDataAccess]: Error creating user: ${error}`)
		throw AppError.from(error, 'userDataAccess')
	}
}
```

### Refactored with Neverthrow

#### 1. Route Handler (unchanged)

```typescript
// auth.routes.ts
router.post(
	'/register',
	validateRequest(registerUserRequestSchema),
	authController.register,
)
```

#### 2. Controller

```typescript
// auth.controller.ts
register: async (req: Request, res: Response) => {
	const { email, password, confirmPassword } = req.body as TRegisterUserRequest

	const result = await cognito
		.signUpUser({ email, password, confirmPassword })
		.andThen((response) => {
			if (!response.UserSub) {
				return err(
					AppError.validation('User not created - no user ID returned'),
				)
			}
			return ok(response)
		})
		.andThen((response) =>
			createUser({ id: response.UserSub, email }).map((user) => ({
				user,
				response,
			})),
		)

	result.match(
		// Success case
		({ user, response }) => {
			logger.info(`[authController]: User created: ${user.id}`)

			const authResponse: TRegisterUserResponse = {
				message:
					'Registration successful. Please check your email for verification code.',
				user: {
					id: response.UserSub,
					email,
				},
			}

			res.status(StatusCodes.CREATED).json(authResponse)
		},
		// Error case
		(error) => {
			logger.error(`[authController]: Error registering user: ${error}`)
			const err = standardizeError(error)
			handleError(res, err, 'authController')
		},
	)
}
```

#### 3. Service

```typescript
// auth.services.ts
public signUpUser({
  email,
  password,
  confirmPassword,
}: TRegisterUserRequest): ResultAsync<SignUpCommandOutput, AppError> {
  if (password !== confirmPassword) {
    return errAsync(AppError.validation('Passwords do not match', undefined, 'authService'))
  }

  const userId = crypto.randomUUID()

  const command = new SignUpCommand({
    ClientId: this.clientId,
    Username: userId,
    Password: password,
    UserAttributes: [
      {
        Name: 'email',
        Value: email,
      },
    ],
    SecretHash: this.generateHash(userId),
  })

  return ResultAsync.fromPromise(
    this.client.send(command),
    error => AppError.from(error, 'authService')
  )
}
```

#### 4. Data Access

```typescript
// user.data-access.ts
const createUser = (userData: TInsertUser): ResultAsync<TUser, AppError> => {
	return ResultAsync.fromPromise(
		Promise.resolve().then(() => {
			const validatedData = insertUserSchema.parse(userData)

			return db
				.insert(usersTable)
				.values(validatedData)
				.returning()
				.then(([user]) => selectUserSchema.parse(user))
		}),
		(error) => {
			logger.error(`[userDataAccess]: Error creating user: ${error}`)
			return AppError.from(error, 'userDataAccess')
		},
	)
}
```

## Enhanced Error Handling

### Enhancing tryCatch with Standardized Errors

Our current `tryCatch` utility can be enhanced to automatically standardize errors, providing more type safety:

```typescript
// Enhanced Result type with standardized error
interface Success<T> {
	data: T
	error: null
}

interface Failure<E extends IStandardizedError> {
	data: null
	error: E
}

type EnhancedResult<T, E extends IStandardizedError = IStandardizedError> =
	| Success<T>
	| Failure<E>

// Error type enum for more precise error typing
enum ErrorType {
	Validation = 'ValidationError',
	NotFound = 'NotFoundError',
	Unauthorized = 'UnauthorizedError',
	Forbidden = 'ForbiddenError',
	Conflict = 'ConflictError',
	Internal = 'InternalError',
	External = 'ExternalError',
	Unknown = 'UnknownError',
}

// Enhanced tryCatch with standardized errors
const enhancedTryCatch = async <
	T,
	E extends IStandardizedError = IStandardizedError,
>(
	promise: Promise<T>,
	context: string = 'unknown',
): Promise<EnhancedResult<T, E>> => {
	try {
		const data = await promise
		return { data, error: null }
	} catch (error: unknown) {
		const standardizedError = standardizeError(error) as E

		// Add context if not already present
		if (!standardizedError.service) {
			standardizedError.service = context
		}

		logger.error(`[${context}]: ${standardizedError.message}`)
		return { data: null, error: standardizedError }
	}
}
```

Usage example:

```typescript
// Controller with enhanced tryCatch
register: async (req: Request, res: Response) => {
	const { email, password, confirmPassword } = req.body as TRegisterUserRequest

	const { data: response, error } = await enhancedTryCatch(
		cognito.signUpUser({ email, password, confirmPassword }),
		'authController',
	)

	if (error) {
		// Error is already standardized
		handleError(res, error, 'authController')
		return
	}

	if (!response.UserSub) {
		const validationError = AppError.validation(
			'User not created - no user ID returned',
		)
		handleError(res, standardizeError(validationError), 'authController')
		return
	}

	const { data: user, error: userError } = await enhancedTryCatch(
		createUser({ id: response.UserSub, email }),
		'authController',
	)

	if (userError) {
		// Error is already standardized
		handleError(res, userError, 'authController')
		return
	}

	// Rest of the function remains the same
}
```

### Neverthrow's Type-Safe Error Handling

Neverthrow provides excellent type safety for errors through its `Result` type. You can define specific error types for each function, allowing for precise error handling:

```typescript
// Define domain-specific error types
type AuthError =
  | { type: 'PasswordMismatch'; message: string }
  | { type: 'UserExists'; message: string }
  | { type: 'ServiceUnavailable'; message: string }

type DatabaseError =
  | { type: 'ConnectionFailed'; message: string }
  | { type: 'QueryFailed'; message: string }
  | { type: 'ValidationFailed'; message: string; details: unknown }

// Service with specific error type
public signUpUser({
  email,
  password,
  confirmPassword,
}: TRegisterUserRequest): ResultAsync<SignUpCommandOutput, AuthError> {
  if (password !== confirmPassword) {
    return errAsync({
      type: 'PasswordMismatch',
      message: 'Passwords do not match'
    })
  }

  // Rest of the function...

  return ResultAsync.fromPromise(
    this.client.send(command),
    (error): AuthError => {
      if (isCognitoError(error) && error.__type === 'UsernameExistsException') {
        return { type: 'UserExists', message: 'User already exists' }
      }
      return { type: 'ServiceUnavailable', message: 'Service unavailable' }
    }
  )
}
```

This allows for precise error handling in the controller:

```typescript
// Controller with type-safe error handling
register: async (req: Request, res: Response) => {
	const { email, password, confirmPassword } = req.body as TRegisterUserRequest

	const result = await cognito
		.signUpUser({ email, password, confirmPassword })
		.andThen((response) => {
			if (!response.UserSub) {
				return err({
					type: 'ValidationFailed',
					message: 'User not created - no user ID returned',
					details: null,
				})
			}
			return ok(response)
		})
		.andThen((response) =>
			createUser({ id: response.UserSub, email }).map((user) => ({
				user,
				response,
			})),
		)

	result.match(
		// Success case
		({ user, response }) => {
			// Success handling...
		},
		// Error case with type discrimination
		(error) => {
			switch (error.type) {
				case 'PasswordMismatch':
					res.status(StatusCodes.BAD_REQUEST).json({ message: error.message })
					break
				case 'UserExists':
					res.status(StatusCodes.CONFLICT).json({ message: error.message })
					break
				case 'ValidationFailed':
					res.status(StatusCodes.BAD_REQUEST).json({
						message: error.message,
						details: error.details,
					})
					break
				case 'ConnectionFailed':
				case 'QueryFailed':
				case 'ServiceUnavailable':
					res
						.status(StatusCodes.INTERNAL_SERVER_ERROR)
						.json({ message: error.message })
					break
				default:
					// Exhaustive type checking - TypeScript will error if we miss a case
					const _exhaustiveCheck: never = error
					res.status(StatusCodes.INTERNAL_SERVER_ERROR).json({
						message: 'Unknown error occurred',
					})
			}
		},
	)
}
```

### Combining Results with Different Error Types

Neverthrow provides utilities for combining results with different error types:

```typescript
import { Result, ResultAsync, ok, err, fromPromise } from 'neverthrow'

// Function that returns a Result with AuthError
function validateUser(user: UserInput): Result<User, AuthError> {
	// Validation logic...
}

// Function that returns a Result with DatabaseError
function saveUser(user: User): ResultAsync<User, DatabaseError> {
	// Database logic...
}

// Combining results with different error types
function createUser(
	input: UserInput,
): ResultAsync<User, AuthError | DatabaseError> {
	return validateUser(input).asyncAndThen((validUser) => saveUser(validUser))
}

// Using the combined result
createUser(input).match(
	(user) => {
		// Success case
	},
	(error) => {
		// Type narrowing with discriminated union
		if (error.type === 'PasswordMismatch' || error.type === 'UserExists') {
			// Handle AuthError
		} else {
			// Handle DatabaseError
		}
	},
)
```

## Conclusion

### When to Use Custom tryCatch:

- For simpler applications with straightforward error flows
- When introducing functional error handling incrementally
- When minimizing dependencies is a priority
- For teams more familiar with traditional try/catch patterns

### When to Use Neverthrow:

- For complex applications with sophisticated error handling needs
- When strong type safety and composition are priorities
- For teams comfortable with functional programming concepts
- When building a new application from scratch

Our custom `tryCatch` utility provides a good balance of simplicity and error handling for many use cases, while neverthrow offers more power and safety at the cost of a steeper learning curve and more extensive refactoring.

### Enhanced Error Handling Decision:

If you need more precise error typing but want to keep your current approach:

1. Enhance the `tryCatch` utility with automatic error standardization
2. Add an error type enum for more precise error typing
3. Use type guards for error discrimination

If you need comprehensive error handling with full type safety:

1. Adopt neverthrow for its strong typing and composition capabilities
2. Define domain-specific error types with discriminated unions
3. Leverage neverthrow's combinators for complex flows
